[2022-05-30 09:54:15 +0200] [7572] [INFO] Starting gunicorn 20.1.0
[2022-05-30 09:54:15 +0200] [7572] [INFO] Listening at: http://0.0.0.0:8080 (7572)
[2022-05-30 09:54:15 +0200] [7572] [INFO] Using worker: sync
[2022-05-30 09:54:15 +0200] [7574] [INFO] Booting worker with pid: 7574
[2022-05-30 09:54:15 +0200] [7574] [ERROR] Exception in worker process
Traceback (most recent call last):
  File "/usr/local/lib/python3.8/dist-packages/gunicorn/arbiter.py", line 589, in spawn_worker
    worker.init_process()
  File "/usr/local/lib/python3.8/dist-packages/gunicorn/workers/base.py", line 134, in init_process
    self.load_wsgi()
  File "/usr/local/lib/python3.8/dist-packages/gunicorn/workers/base.py", line 146, in load_wsgi
    self.wsgi = self.app.wsgi()
  File "/usr/local/lib/python3.8/dist-packages/gunicorn/app/base.py", line 67, in wsgi
    self.callable = self.load()
  File "/usr/local/lib/python3.8/dist-packages/gunicorn/app/wsgiapp.py", line 58, in load
    return self.load_wsgiapp()
  File "/usr/local/lib/python3.8/dist-packages/gunicorn/app/wsgiapp.py", line 48, in load_wsgiapp
    return util.import_app(self.app_uri)
  File "/usr/local/lib/python3.8/dist-packages/gunicorn/util.py", line 359, in import_app
    mod = importlib.import_module(module)
  File "/usr/lib/python3.8/importlib/__init__.py", line 127, in import_module
    return _bootstrap._gcd_import(name[level:], package, level)
  File "<frozen importlib._bootstrap>", line 1014, in _gcd_import
  File "<frozen importlib._bootstrap>", line 991, in _find_and_load
  File "<frozen importlib._bootstrap>", line 973, in _find_and_load_unlocked
ModuleNotFoundError: No module named 'app'
[2022-05-30 09:54:15 +0200] [7574] [INFO] Worker exiting (pid: 7574)
[2022-05-30 09:54:15 +0200] [7575] [INFO] Booting worker with pid: 7575
[2022-05-30 09:54:15 +0200] [7575] [ERROR] Exception in worker process
Traceback (most recent call last):
  File "/usr/local/lib/python3.8/dist-packages/gunicorn/arbiter.py", line 589, in spawn_worker
    worker.init_process()
  File "/usr/local/lib/python3.8/dist-packages/gunicorn/workers/base.py", line 134, in init_process
    self.load_wsgi()
  File "/usr/local/lib/python3.8/dist-packages/gunicorn/workers/base.py", line 146, in load_wsgi
    self.wsgi = self.app.wsgi()
  File "/usr/local/lib/python3.8/dist-packages/gunicorn/app/base.py", line 67, in wsgi
    self.callable = self.load()
  File "/usr/local/lib/python3.8/dist-packages/gunicorn/app/wsgiapp.py", line 58, in load
    return self.load_wsgiapp()
  File "/usr/local/lib/python3.8/dist-packages/gunicorn/app/wsgiapp.py", line 48, in load_wsgiapp
    return util.import_app(self.app_uri)
  File "/usr/local/lib/python3.8/dist-packages/gunicorn/util.py", line 359, in import_app
    mod = importlib.import_module(module)
  File "/usr/lib/python3.8/importlib/__init__.py", line 127, in import_module
    return _bootstrap._gcd_import(name[level:], package, level)
  File "<frozen importlib._bootstrap>", line 1014, in _gcd_import
  File "<frozen importlib._bootstrap>", line 991, in _find_and_load
  File "<frozen importlib._bootstrap>", line 973, in _find_and_load_unlocked
ModuleNotFoundError: No module named 'app'
[2022-05-30 09:54:15 +0200] [7575] [INFO] Worker exiting (pid: 7575)
Traceback (most recent call last):
  File "/usr/local/lib/python3.8/dist-packages/gunicorn/arbiter.py", line 202, in run
    self.manage_workers()
  File "/usr/local/lib/python3.8/dist-packages/gunicorn/arbiter.py", line 551, in manage_workers
    self.spawn_workers()
  File "/usr/local/lib/python3.8/dist-packages/gunicorn/arbiter.py", line 623, in spawn_workers
    time.sleep(0.1 * random.random())
  File "/usr/local/lib/python3.8/dist-packages/gunicorn/arbiter.py", line 242, in handle_chld
    self.reap_workers()
  File "/usr/local/lib/python3.8/dist-packages/gunicorn/arbiter.py", line 525, in reap_workers
    raise HaltServer(reason, self.WORKER_BOOT_ERROR)
gunicorn.errors.HaltServer: <HaltServer 'Worker failed to boot.' 3>

During handling of the above exception, another exception occurred:

Traceback (most recent call last):
  File "/usr/local/bin/gunicorn", line 8, in <module>
    sys.exit(run())
  File "/usr/local/lib/python3.8/dist-packages/gunicorn/app/wsgiapp.py", line 67, in run
    WSGIApplication("%(prog)s [OPTIONS] [APP_MODULE]").run()
  File "/usr/local/lib/python3.8/dist-packages/gunicorn/app/base.py", line 231, in run
    super().run()
  File "/usr/local/lib/python3.8/dist-packages/gunicorn/app/base.py", line 72, in run
    Arbiter(self).run()
  File "/usr/local/lib/python3.8/dist-packages/gunicorn/arbiter.py", line 229, in run
    self.halt(reason=inst.reason, exit_status=inst.exit_status)
  File "/usr/local/lib/python3.8/dist-packages/gunicorn/arbiter.py", line 342, in halt
    self.stop()
  File "/usr/local/lib/python3.8/dist-packages/gunicorn/arbiter.py", line 393, in stop
    time.sleep(0.1)
  File "/usr/local/lib/python3.8/dist-packages/gunicorn/arbiter.py", line 242, in handle_chld
    self.reap_workers()
  File "/usr/local/lib/python3.8/dist-packages/gunicorn/arbiter.py", line 525, in reap_workers
    raise HaltServer(reason, self.WORKER_BOOT_ERROR)
gunicorn.errors.HaltServer: <HaltServer 'Worker failed to boot.' 3>
[2022-05-30 09:54:30 +0200] [7578] [INFO] Starting gunicorn 20.1.0
[2022-05-30 09:54:30 +0200] [7578] [INFO] Listening at: http://0.0.0.0:8080 (7578)
[2022-05-30 09:54:30 +0200] [7578] [INFO] Using worker: sync
[2022-05-30 09:54:30 +0200] [7580] [INFO] Booting worker with pid: 7580
[2022-05-30 09:54:30 +0200] [7580] [ERROR] Exception in worker process
Traceback (most recent call last):
  File "/usr/local/lib/python3.8/dist-packages/gunicorn/arbiter.py", line 589, in spawn_worker
    worker.init_process()
  File "/usr/local/lib/python3.8/dist-packages/gunicorn/workers/base.py", line 134, in init_process
    self.load_wsgi()
  File "/usr/local/lib/python3.8/dist-packages/gunicorn/workers/base.py", line 146, in load_wsgi
    self.wsgi = self.app.wsgi()
  File "/usr/local/lib/python3.8/dist-packages/gunicorn/app/base.py", line 67, in wsgi
    self.callable = self.load()
  File "/usr/local/lib/python3.8/dist-packages/gunicorn/app/wsgiapp.py", line 58, in load
    return self.load_wsgiapp()
  File "/usr/local/lib/python3.8/dist-packages/gunicorn/app/wsgiapp.py", line 48, in load_wsgiapp
    return util.import_app(self.app_uri)
  File "/usr/local/lib/python3.8/dist-packages/gunicorn/util.py", line 359, in import_app
    mod = importlib.import_module(module)
  File "/usr/lib/python3.8/importlib/__init__.py", line 127, in import_module
    return _bootstrap._gcd_import(name[level:], package, level)
  File "<frozen importlib._bootstrap>", line 1014, in _gcd_import
  File "<frozen importlib._bootstrap>", line 991, in _find_and_load
  File "<frozen importlib._bootstrap>", line 973, in _find_and_load_unlocked
ModuleNotFoundError: No module named 'app'
[2022-05-30 09:54:30 +0200] [7580] [INFO] Worker exiting (pid: 7580)
[2022-05-30 09:54:30 +0200] [7578] [INFO] Shutting down: Master
[2022-05-30 09:54:30 +0200] [7578] [INFO] Reason: Worker failed to boot.
